Workbook

Sheet Article Tracker
A1: # | B1: Category | C1: Article Title (User Question) | D1: File Path | E1: User Intent | F1: Status | G1: Day | H1: Date Done | I1: Writer | J1: Links OK | K1: Screenshots | L1: Notes
B2: A. Getting Started
A3: 1 | B3: Getting Started | C3: What is SparrowGenie | D3: getting-started/what-is-sparrowgenie.md | E3: What does this product do? | F3: Not Started | G3: Day 1
A4: 2 | B4: Getting Started | C4: Setting up your account | D4: getting-started/setting-up-your-account.md | E4: I signed up, now what? | F4: Not Started | G4: Day 1
A5: 3 | B5: Getting Started | C5: How to invite your team | D5: getting-started/how-to-invite-your-team.md | E5: How do I get colleagues in? | F5: Not Started | G5: Day 1
A6: 4 | B6: Getting Started | C6: Understanding roles | D6: getting-started/understanding-roles.md | E6: What can different people do? | F6: Not Started | G6: Day 1
A7: 5 | B7: Getting Started | C7: Owner vs Manager vs Participant | D7: getting-started/owner-vs-manager-vs-participant.md | E7: Who can do what exactly? | F7: Not Started | G7: Day 1
A8: 6 | B8: Getting Started | C8: Quick start: First project in 10 min | D8: getting-started/quick-start-your-first-project-in-10-minutes.md | E8: Just show me the fastest path | F8: Not Started | G8: Day 2
B9: B. Knowledge Hub
A10: 7 | B10: Knowledge Hub | C10: What is the Knowledge Hub | D10: knowledge-hub/what-is-the-knowledge-hub.md | E10: Why does this matter? | F10: Not Started | G10: Day 2
A11: 8 | B11: Knowledge Hub | C11: How to upload documents | D11: knowledge-hub/how-to-upload-documents.md | E11: How do I get files in? | F11: Not Started | G11: Day 2
A12: 9 | B12: Knowledge Hub | C12: Supported file types (KH) | D12: knowledge-hub/supported-file-types.md | E12: Can I upload Word/PDF? | F12: Not Started | G12: Day 2
A13: 10 | B13: Knowledge Hub | C13: How to organize with folders | D13: knowledge-hub/how-to-organize-with-folders.md | E13: My KH is a mess | F13: Not Started | G13: Day 2
A14: 11 | B14: Knowledge Hub | C14: How the AI learns from your content | D14: knowledge-hub/how-the-ai-learns-from-your-content.md | E14: How does AI know answers? | F14: Not Started | G14: Day 3
A15: 12 | B15: Knowledge Hub | C15: How to test KH coverage | D15: knowledge-hub/how-to-test-knowledge-hub-coverage.md | E15: Is my KH ready? | F15: Not Started | G15: Day 3
A16: 13 | B16: Knowledge Hub | C16: How to improve AI answer quality | D16: knowledge-hub/how-to-improve-ai-answer-quality.md | E16: AI keeps getting things wrong | F16: Not Started | G16: Day 3
B17: C. Projects — Creating
A18: 14 | B18: Projects — Creating | C18: What is a Project | D18: projects/creating/what-is-a-project.md | E18: What does 'project' mean here? | F18: Not Started | G18: Day 3
A19: 15 | B19: Projects — Creating | C19: How to create a new project | D19: projects/creating/how-to-create-a-new-project.md | E19: I need to start on this RFP | F19: Not Started | G19: Day 3
A20: 16 | B20: Projects — Creating | C20: What you need before starting | D20: projects/creating/what-you-need-before-starting.md | E20: Am I ready to create a project? | F20: Not Started | G20: Day 4
B21: D. Projects — Importing
A22: 17 | B22: Projects — Importing | C22: How to import your RFP | D22: projects/importing/how-to-import-your-rfp.md | E22: How do I upload my RFP? | F22: Not Started | G22: Day 4
A23: 18 | B23: Projects — Importing | C23: Supported import formats | D23: projects/importing/supported-import-formats.md | E23: Can I import Excel/CSV? | F23: Not Started | G23: Day 4
A24: 19 | B24: Projects — Importing | C24: How to clean your file before importing | D24: projects/importing/how-to-clean-your-file-before-importing.md | E24: File has weird formatting | F24: Not Started | G24: Day 4
A25: 20 | B25: Projects — Importing | C25: My file won't upload | D25: projects/importing/my-file-wont-upload.md | E25: I get an error uploading | F25: Not Started | G25: Day 4
B26: E. Projects — Mapping
A27: 21 | B27: Projects — Mapping | C27: What is mapping and why do I need it | D27: projects/mapping/what-is-mapping-and-why-do-i-need-it.md | E27: What is this step? | F27: Not Started | G27: Day 5
A28: 22 | B28: Projects — Mapping | C28: How to map sections and questions | D28: projects/mapping/how-to-map-sections-and-questions.md | E28: Show me how to map | F28: Not Started | G28: Day 5
A29: 23 | B29: Projects — Mapping | C29: Using dropdown vs manual mapping | D29: projects/mapping/using-dropdown-vs-manual-mapping.md | E29: What's the difference? | F29: Not Started | G29: Day 5
A30: 24 | B30: Projects — Mapping | C30: How auto-map works | D30: projects/mapping/how-auto-map-works.md | E30: Can the system do it for me? | F30: Not Started | G30: Day 5
A31: 25 | B31: Projects — Mapping | C31: How to undo, redo, or reset mapping | D31: projects/mapping/how-to-undo-redo-or-reset-mapping.md | E31: I messed up, how to go back? | F31: Not Started | G31: Day 5
A32: 26 | B32: Projects — Mapping | C32: How to review and finish mapping | D32: projects/mapping/how-to-review-and-finish-mapping.md | E32: Am I done? What's next? | F32: Not Started | G32: Day 6
A33: 27 | B33: Projects — Mapping | C33: The AI mapped something wrong | D33: projects/mapping/the-ai-mapped-something-wrong.md | E33: Auto-map got stuff wrong | F33: Not Started | G33: Day 6
B34: F. Projects — AI Answer Fill
A35: 28 | B35: Projects — AI Answer Fill | C35: How does AI answer fill work | D35: projects/ai-answer-fill/how-does-ai-answer-fill-work.md | E35: How does Genie fill answers? | F35: Not Started | G35: Day 6
A36: 29 | B36: Projects — AI Answer Fill | C36: How to auto-fill answers | D36: projects/ai-answer-fill/how-to-auto-fill-answers.md | E36: How do I trigger AI fill? | F36: Not Started | G36: Day 6
A37: 30 | B37: Projects — AI Answer Fill | C37: How to edit an AI answer | D37: projects/ai-answer-fill/how-to-edit-an-ai-answer.md | E37: Answer is close but not right | F37: Not Started | G37: Day 6
A38: 31 | B38: Projects — AI Answer Fill | C38: The AI answer is wrong or missing | D38: projects/ai-answer-fill/the-ai-answer-is-wrong-or-missing.md | E38: AI got it wrong / left blank | F38: Not Started | G38: Day 7
A39: 32 | B39: Projects — AI Answer Fill | C39: How to improve AI answers | D39: projects/ai-answer-fill/how-to-improve-ai-answers.md | E39: How to make AI better over time? | F39: Not Started | G39: Day 7
B40: G. Projects — Collaborating
...

Sheet Summary
A1: Day | B1: Date | C1: Articles Planned | D1: Articles Done | E1: % Complete | F1: Phase
A2: Day 1 | B2: Apr 3 | C2: =COUNTIF('Article Tracker'!G:G,"Day 1") -> 5 | D2: =COUNTIFS('Article Tracker'!G:G,"Day 1",'Article Tracker'!F:F,"Done") -> 0 | E2: =IF(C2=0,0,D2/C2) -> 0 | F2: Getting Started basics
A3: Day 2 | B3: Apr 4 | C3: =COUNTIF('Article Tracker'!G:G,"Day 2") -> 5 | D3: =COUNTIFS('Article Tracker'!G:G,"Day 2",'Article Tracker'!F:F,"Done") -> 0 | E3: =IF(C3=0,0,D3/C3) -> 0 | F3: Quick Start + Knowledge Hub
A4: Day 3 | B4: Apr 7 | C4: =COUNTIF('Article Tracker'!G:G,"Day 3") -> 5 | D4: =COUNTIFS('Article Tracker'!G:G,"Day 3",'Article Tracker'!F:F,"Done") -> 0 | E4: =IF(C4=0,0,D4/C4) -> 0 | F4: AI learning + Project creation
A5: Day 4 | B5: Apr 8 | C5: =COUNTIF('Article Tracker'!G:G,"Day 4") -> 5 | D5: =COUNTIFS('Article Tracker'!G:G,"Day 4",'Article Tracker'!F:F,"Done") -> 0 | E5: =IF(C5=0,0,D5/C5) -> 0 | F5: Pre-import + Importing
A6: Day 5 | B6: Apr 9 | C6: =COUNTIF('Article Tracker'!G:G,"Day 5") -> 5 | D6: =COUNTIFS('Article Tracker'!G:G,"Day 5",'Article Tracker'!F:F,"Done") -> 0 | E6: =IF(C6=0,0,D6/C6) -> 0 | F6: Mapping
A7: Day 6 | B7: Apr 10 | C7: =COUNTIF('Article Tracker'!G:G,"Day 6") -> 5 | D7: =COUNTIFS('Article Tracker'!G:G,"Day 6",'Article Tracker'!F:F,"Done") -> 0 | E7: =IF(C7=0,0,D7/C7) -> 0 | F7: Finish mapping + AI fill
A8: Day 7 | B8: Apr 11 | C8: =COUNTIF('Article Tracker'!G:G,"Day 7") -> 5 | D8: =COUNTIFS('Article Tracker'!G:G,"Day 7",'Article Tracker'!F:F,"Done") -> 0 | E8: =IF(C8=0,0,D8/C8) -> 0 | F8: AI troubleshoot + Collaboration
A9: Day 8 | B9: Apr 14 | C9: =COUNTIF('Article Tracker'!G:G,"Day 8") -> 5 | D9: =COUNTIFS('Article Tracker'!G:G,"Day 8",'Article Tracker'!F:F,"Done") -> 0 | E9: =IF(C9=0,0,D9/C9) -> 0 | F9: Notifications + Reviewing
A10: Day 9 | B10: Apr 15 | C10: =COUNTIF('Article Tracker'!G:G,"Day 9") -> 5 | D10: =COUNTIFS('Article Tracker'!G:G,"Day 9",'Article Tracker'!F:F,"Done") -> 0 | E10: =IF(C10=0,0,D10/C10) -> 0 | F10: Tracking progress
A11: Day 10 | B11: Apr 16 | C11: =COUNTIF('Article Tracker'!G:G,"Day 10") -> 5 | D11: =COUNTIFS('Article Tracker'!G:G,"Day 10",'Article Tracker'!F:F,"Done") -> 0 | E11: =IF(C11=0,0,D11/C11) -> 0 | F11: Exporting + Settings
A12: Day 11 | B12: Apr 17 | C12: =COUNTIF('Article Tracker'!G:G,"Day 11") -> 5 | D12: =COUNTIFS('Article Tracker'!G:G,"Day 11",'Article Tracker'!F:F,"Done") -> 0 | E12: =IF(C12=0,0,D12/C12) -> 0 | F12: Settings + Landing pages
A13: Day 12 | B13: Apr 18 | C13: =COUNTIF('Article Tracker'!G:G,"Day 12") -> 1 | D13: =COUNTIFS('Article Tracker'!G:G,"Day 12",'Article Tracker'!F:F,"Done") -> 0 | E13: =IF(C13=0,0,D13/C13) -> 0 | F13: Review day + final landing page
A14: TOTAL | C14: =SUM(C2:C13) -> 56 | D14: =SUM(D2:D13) -> 0 | E14: =IF(C14=0,0,D14/C14) -> 0
